Workbook

Sheet Read Me
A1: Passage rune workbook
A2: Made 2026-10-22 from design/14-rune-sets-v0.md and design/affinities/water.md. Nothing here is in the game yet.
A4: Sheets
A5: Affinities: every affinity, its rule, status and rune count, with a link to its sheet. The proposed seven are listed below it.
A6: Base Runes: every base rune in one list, with its character. This is where a rune's name and character live.
A7: Universal Runes: the 28 universal pairs anyone can add to a skill, with characters.
A8: One sheet per affinity: each rune as a skill, as a means, what it releases with its opposite, and the skills built on it.
A10: Colours
A11: Blue text: type here.
A12: Green text: pulled from another sheet. Change it at its source (names and characters on Base Runes).
A13: Black text: worked out on this sheet (opposites, counts).
A14: Yellow fill: not written yet (water is the only affinity with its means and together columns filled).
... A34: 2026-10-22: the base runes were replaced by the revised set (design/runes-data/revised-rune-set.md), approved by Brent. IDs, characters and opposite pairs are unchanged; names, meanings, roles, draws and the skills on each rune changed. Water's means and together columns were kept only for the runes that survived.

Sheet Affinities
A1: Affinity | B1: Rule | C1: Status | D1: Source | E1: Base runes | F1: Pairs | G1: Sheet | I1: Heat | J1: Value | K1: Substance | L1: Value | M1: Vitality | N1: Value | O1: Light | P1: Value | Q1: Mind/Matter | R1: Value
A2: Water | B2: Moves bodies (shove and Crush); works the water that is already there (wetness) | C2: Deep dive v0 | D2: existing (design/05); MODEL: wetness, from C | E2: =COUNTIF('Base Runes'!$B:$B,$A2) -> 16 | F2: =E2/2 -> 8 | G2: Water | J2: ='Slider Links'!G2 -> -0.3 | L2: ='Slider Links'!H2 -> -0.6 | N2: ='Slider Links'!I2 -> 0.5 | P2: ='Slider Links'!J2 -> 0 | R2: ='Slider Links'!K2 -> 0.6
A3: Fire | B3: Runs on its own heat | C3: First pass | E3: =COUNTIF('Base Runes'!$B:$B,$A3) -> 10 | F3: =E3/2 -> 5 | G3: Fire | J3: ='Slider Links'!G3 -> 1 | L3: ='Slider Links'!H3 -> -0.3 | N3: ='Slider Links'!I3 -> 0 | P3: ='Slider Links'!J3 -> 0.6 | R3: ='Slider Links'!K3 -> 0
A4: Earth | B4: Builds stone that stays | C4: First pass | E4: =COUNTIF('Base Runes'!$B:$B,$A4) -> 10 | F4: =E4/2 -> 5 | G4: Earth | J4: ='Slider Links'!G4 -> 0 | L4: ='Slider Links'!H4 -> 1 | N4: ='Slider Links'!I4 -> 0.2 | P4: ='Slider Links'!J4 -> -0.2 | R4: ='Slider Links'!K4 -> 1
A5: Wind | B5: Paid for by moving (Slipstream) | C5: First pass | E5: =COUNTIF('Base Runes'!$B:$B,$A5) -> 10 | F5: =E5/2 -> 5 | G5: Wind | J5: ='Slider Links'!G5 -> 0 | L5: ='Slider Links'!H5 -> -0.8 | N5: ='Slider Links'!I5 -> 0.2 | P5: ='Slider Links'!J5 -> 0 | R5: ='Slider Links'!K5 -> 0.4
A6: Lightning | B6: Marks a target, then overloads it | C6: First pass | E6: =COUNTIF('Base Runes'!$B:$B,$A6) -> 10 | F6: =E6/2 -> 5 | G6: Lightning | J6: ='Slider Links'!G6 -> 0.6 | L6: ='Slider Links'!H6 -> -0.5 | N6: ='Slider Links'!I6 -> 0 | P6: ='Slider Links'!J6 -> 0.7 | R6: ='Slider Links'!K6 -> -0.1
A7: Ice | B7: What it freezes stays frozen | C7: First pass (new 2026-10-22) | D7: B 2026-10-21: ice is its own affinity, taking water's Freeze; MODEL: the rule | E7: =COUNTIF('Base Runes'!$B:$B,$A7) -> 10 | F7: =E7/2 -> 5 | G7: Ice | J7: ='Slider Links'!G7 -> -1 | L7: ='Slider Links'!H7 -> 0.5 | N7: ='Slider Links'!I7 -> -0.3 | P7: ='Slider Links'!J7 -> 0.1 | R7: ='Slider Links'!K7 -> 0.2
A8: Dark | B8: Strongest where the light is weakest | C8: First pass (new 2026-10-22) | D8: B 2026-10-21: dark is an affinity; MODEL: the rule | E8: =COUNTIF('Base Runes'!$B:$B,$A8) -> 10 | F8: =E8/2 -> 5 | G8: Dark | J8: ='Slider Links'!G8 -> -0.3 | L8: ='Slider Links'!H8 -> -0.3 | N8: ='Slider Links'!I8 -> -0.2 | P8: ='Slider Links'!J8 -> -1 | R8: ='Slider Links'!K8 -> -0.4
A9: Metal | B9: Worn and carried metal is its material | C9: First pass | D9: MODEL | E9: =COUNTIF('Base Runes'!$B:$B,$A9) -> 10 | F9: =E9/2 -> 5 | G9: Metal | J9: ='Slider Links'!G9 -> 0 | L9: ='Slider Links'!H9 -> 0.8 | N9: ='Slider Links'!I9 -> -0.3 | P9: ='Slider Links'!J9 -> 0.2 | R9: ='Slider Links'!K9 -> 1
A10: Blood | B10: Works the blood that is already out | C10: First pass | D10: C: blood storage and blood-to-metal techniques exist; MODEL: the rule | E10: =COUNTIF('Base Runes'!$B:$B,$A10) -> 10 | F10: =E10/2 -> 5 | G10: Blood | J10: ='Slider Links'!G10 -> 0.3 | L10: ='Slider Links'!H10 -> -0.5 | N10: ='Slider Links'!I10 -> 0.6 | P10: ='Slider Links'!J10 -> -0.2 | R10: ='Slider Links'!K10 -> 0.8
A11: Life | B11: Works inside living bodies | C11: First pass | D11: C: life practitioners work inside a body, with consent; MODEL: the rule | E11: =COUNTIF('Base Runes'!$B:$B,$A11) -> 10 | F11: =E11/2 -> 5 | G11: Life | J11: ='Slider Links'!G11 -> 0.3 | L11: ='Slider Links'!H11 -> 0 | N11: ='Slider Links'!I11 -> 1 | P11: ='Slider Links'!J11 -> 0.2 | R11: ='Slider Links'!K11 -> 0.4
A12: Death | B12: What has died stays useful | C12: First pass | D12: C: death affinity and undeath exist; MODEL: the rule | E12: =COUNTIF('Base Runes'!$B:$B,$A12) -> 10 | F12: =E12/2 -> 5 | G12: Death | J12: ='Slider Links'!G12 -> -0.5 | L12: ='Slider Links'!H12 -> 0.2 | N12: ='Slider Links'!I12 -> -1 | P12: ='Slider Links'!J12 -> -0.4 | R12: ='Slider Links'!K12 -> 0
A13: Nature | B13: Grows from the ground and keeps growing | C13: First pass | D13: C: nature is named; MODEL: the rule | E13: =COUNTIF('Base Runes'!$B:$B,$A13) -> 10 | F13: =E13/2 -> 5 | G13: Nature | J13: ='Slider Links'!G13 -> 0 | L13: ='Slider Links'!H13 -> 0.2 | N13: ='Slider Links'!I13 -> 1 | P13: ='Slider Links'!J13 -> 0.1 | R13: ='Slider Links'!K13 -> 0.5
A14: Light | B14: Straight and instant; reveals the hidden | C14: First pass | D14: MODEL: the rule | E14: =COUNTIF('Base Runes'!$B:$B,$A14) -> 10 | F14: =E14/2 -> 5 | G14: Light | J14: ='Slider Links'!G14 -> 0.4 | L14: ='Slider Links'!H14 -> -0.4 | N14: ='Slider Links'!I14 -> 0.3 | P14: ='Slider Links'!J14 -> 1 | R14: ='Slider Links'!K14 -> 0
A15: Dream | B15: The mind | C15: First pass | D15: C: dream is a named, valued affinity; MODEL: the rule | E15: =COUNTIF('Base Runes'!$B:$B,$A15) -> 10 | F15: =E15/2 -> 5 | G15: Dream | J15: ='Slider Links'!G15 -> 0 | L15: ='Slider Links'!H15 -> -0.6 | N15: ='Slider Links'!I15 -> 0 | P15: ='Slider Links'!J15 -> -0.6 | R15: ='Slider Links'!K15 -> -1
A16: Poison | B16: Doses stack inside a body and come due later | C16: First pass | D16: MODEL: the rule | E16: =COUNTIF('Base Runes'!$B:$B,$A16) -> 10 | F16: =E16/2 -> 5 | G16: Poison | J16: ='Slider Links'!G16 -> 0 | L16: ='Slider Links'!H16 -> -0.3 | N16: ='Slider Links'!I16 -> -0.8 | P16: ='Slider Links'!J16 -> -0.6 | R16: ='Slider Links'!K16 -> 0.4
A17: Disease | B17: A cloud that only harms flesh | C17: First pass | D17: B 2026-10-21: renamed from Miasma; C: miasma is flesh-only and armour counters it; MODEL: the rest | E17: =COUNTIF('Base Runes'!$B:$B,$A17) -> 10 | F17: =E17/2 -> 5 | G17: Disease | J17: ='Slider Links'!G17 -> 0.2 | L17: ='Slider Links'!H17 -> -0.5 | N17: ='Slider Links'!I17 -> -1 | P17: ='Slider Links'!J17 -> -0.3 | R17: ='Slider Links'!K17 -> 0.3
A18: Total | E18: =SUM(E2:E17) -> 166 | F18: =SUM(F2:F17) -> 83
A20: Proposed, awaiting your yes or no (no sheets yet)
A21: Sound | C21: Proposed
A22: Gravity | C22: Proposed
A23: Space | C23: Proposed
A24: Time | C24: Proposed
A25: Mind | C25: Proposed
A26: Beast | C26: Proposed
A27: Spirit | C27: Proposed

Sheet Alignment
B1: ='Slider Links'!A2 -> Water | C1: ='Slider Links'!A3 -> Fire | D1: ='Slider Links'!A4 -> Earth | E1: ='Slider Links'!A5 -> Wind | F1: ='Slider Links'!A6 -> Lightning | G1: ='Slider Links'!A7 -> Ice | H1: ='Slider Links'!A8 -> Dark | I1: ='Slider Links'!A9 -> Metal | J1: ='Slider Links'!A10 -> Blood | K1: ='Slider Links'!A11 -> Life | L1: ='Slider Links'!A12 -> Death | M1: ='Slider Links'!A13 -> Nature | N1: ='Slider Links'!A14 -> Light | O1: ='Slider Links'!A15 -> Dream | P1: ='Slider Links'!A16 -> Poison | Q1: ='Slider Links'!A17 -> Disease
A2: ='Slider Links'!A2 -> Water | B2: =IFERROR(SUMPRODUCT('Slider Links'!$G$2:$K$2,'Slider Links'!$G$2:$K$2)/SQRT(SUMSQ('Slider Links'!$G$2:$K$2)*SUMSQ('Slider Links'!$G$2:$K$2)),0) -> 1 | C2: =IFERROR(SUMPRODUCT('Slider Links'!$G$2:$K$2,'Slider Links'!$G$3:$K$3)/SQRT(SUMSQ('Slider Links'!$G$2:$K$2)*SUMSQ('Slider Links'!$G$3:$K$3)),0) -> -0.096793081 | D2: =IFERROR(SUMPRODUCT('Slider Links'!$G$2:$K$2,'Slider Links'!$G$4:$K$4)/SQRT(SUMSQ('Slider Links'!$G$2:$K$2)*SUMSQ('Slider Links'!$G$4:$K$4)),0) -> 0.067346557 | E2: =IFERROR(SUMPRODUCT('Slider Links'!$G$2:$K$2,'Slider Links'!$G$5:$K$5)/SQRT(SUMSQ('Slider Links'!$G$2:$K$2)*SUMSQ('Slider Links'!$G$5:$K$5)),0) -> 0.869003 | F2: =IFERROR(SUMPRODUCT('Slider Links'!$G$2:$K$2,'Slider Links'!$G$6:$K$6)/SQRT(SUMSQ('Slider Links'!$G$2:$K$2)*SUMSQ('Slider Links'!$G$6:$K$6)),0) -> 0.055314225 | G2: =IFERROR(SUMPRODUCT('Slider Links'!$G$2:$K$2,'Slider Links'!$G$7:$K$7)/SQRT(SUMSQ('Slider Links'!$G$2:$K$2)*SUMSQ('Slider Links'!$G$7:$K$7)),0) -> -0.024715017 | H2: =IFERROR(SUMPRODUCT('Slider Links'!$G$2:$K$2,'Slider Links'!$G$8:$K$8)/SQRT(SUMSQ('Slider Links'!$G$2:$K$2)*SUMSQ('Slider Links'!$G$8:$K$8)),0) -> -0.05787694 | I2: =IFERROR(SUMPRODUCT('Slider Links'!$G$2:$K$2,'Slider Links'!$G$9:$K$9)/SQRT(SUMSQ('Slider Links'!$G$2:$K$2)*SUMSQ('Slider Links'!$G$9:$K$9)),0) -> -0.021901895 | J2: =IFERROR(SUMPRODUCT('Slider Links'!$G$2:$K$2,'Slider Links'!$G$10:$K$10)/SQRT(SUMSQ('Slider Links'!$G$2:$K$2)*SUMSQ('Slider Links'!$G$10:$K$10)),0) -> 0.8185453 | K2: =IFERROR(SUMPRODUCT('Slider Links'!$G$2:$K$2,'Slider Links'!$G$11:$K$11)/SQRT(SUMSQ('Slider Links'!$G$2:$K$2)*SUMSQ('Slider Links'!$G$11:$K$11)),0) -> 0.55586019 | L2: =IFERROR(SUMPRODUCT('Slider Links'!$G$2:$K$2,'Slider Links'!$G$12:$K$12)/SQRT(SUMSQ('Slider Links'!$G$2:$K$2)*SUMSQ('Slider Links'!$G$12:$K$12)),0) -> -0.37910623 | M2: =IFERROR(SUMPRODUCT('Slider Links'!$G$2:$K$2,'Slider Links'!$G$13:$K$13)/SQRT(SUMSQ('Slider Links'!$G$2:$K$2)*SUMSQ('Slider Links'!$G$13:$K$13)),0) -> 0.57927436 | N2: =IFERROR(SUMPRODUCT('Slider Links'!$G$2:$K$2,'Slider Links'!$G$14:$K$14)/SQRT(SUMSQ('Slider Links'!$G$2:$K$2)*SUMSQ('Slider Links'!$G$14:$K$14)),0) -> 0.22085197 | O2: =IFERROR(SUMPRODUCT('Slider Links'!$G$2:$K$2,'Slider Links'!$G$15:$K$15)/SQRT(SUMSQ('Slider Links'!$G$2:$K$2)*SUMSQ('Slider Links'!$G$15:$K$15)),0) -> -0.17774365 | P2: =IFERROR(SUMPRODUCT('Slider Links'!$G$2:$K$2,'Slider Links'!$G$16:$K$16)/SQRT(SUMSQ('Slider Links'!$G$2:$K$2)*SUMSQ('Slider Links'!$G$16:$K$16)),0) -> 0.01737489 | Q2: =IFERROR(SUMPRODUCT('Slider Links'!$G$2:$K$2,'Slider Links'!$G$17:$K$17)/SQRT(SUMSQ('Slider Links'!$G$2:$K$2)*SUMSQ('Slider Links'!$G$17:$K$17)),0) -> -0.064088246
A3: ='Slider Links'!A3 -> Fire | B3: =IFERROR(SUMPRODUCT('Slider Links'!$G$3:$K$3,'Slider Links'!$G$2:$K$2)/SQRT(SUMSQ('Slider Links'!$G$3:$K$3)*SUMSQ('Slider Links'!$G$2:$K$2)),0) -> -0.096793081 | C3: =IFERROR(SUMPRODUCT('Slider Links'!$G$3:$K$3,'Slider Links'!$G$3:$K$3)/SQRT(SUMSQ('Slider Links'!$G$3:$K$3)*SUMSQ('Slider Links'!$G$3:$K$3)),0) -> 1 | D3: =IFERROR(SUMPRODUCT('Slider Links'!$G$3:$K$3,'Slider Links'!$G$4:$K$4)/SQRT(SUMSQ('Slider Links'!$G$3:$K$3)*SUMSQ('Slider Links'!$G$4:$K$4)),0) -> -0.24184306 | E3: =IFERROR(SUMPRODUCT('Slider Links'!$G$3:$K$3,'Slider Links'!$G$5:$K$5)/SQRT(SUMSQ('Slider Links'!$G$3:$K$3)*SUMSQ('Slider Links'!$G$5:$K$5)),0) -> 0.21746411 | F3: =IFERROR(SUMPRODUCT('Slider Links'!$G$3:$K$3,'Slider Links'!$G$6:$K$6)/SQRT(SUMSQ('Slider Links'!$G$3:$K$3)*SUMSQ('Slider Links'!$G$6:$K$6)),0) -> 0.92223239 | G3: =IFERROR(SUMPRODUCT('Slider Links'!$G$3:$K$3,'Slider Links'!$G$7:$K$7)/SQRT(SUMSQ('Slider Links'!$G$3:$K$3)*SUMSQ('Slider Links'!$G$7:$K$7)),0) -> -0.767777 | H3: =IFERROR(SUMPRODUCT('Slider Links'!$G$3:$K$3,'Slider Links'!$G$8:$K$8)/SQRT(SUMSQ('Slider Links'!$G$3:$K$3)*SUMSQ('Slider Links'!$G$8:$K$8)),0) -> -0.57261336 | I3: =IFERROR(SUMPRODUCT('Slider Links'!$G$3:$K$3,'Slider Links'!$G$9:$K$9)/SQRT(SUMSQ('Slider Links'!$G$3:$K$3)*SUMSQ('Slider Links'!$G$9:$K$9)),0) -> -0.074904966 | J3: =IFERROR(SUMPRODUCT('Slider Links'!$G$3:$K$3,'Slider Links'!$G$10:$K$10)/SQRT(SUMSQ('Slider Links'!$G$3:$K$3)*SUMSQ('Slider Links'!$G$10:$K$10)),0) -> 0.23328692 | K3: =IFERROR(SUMPRODUCT('Slider Links'!$G$3:$K$3,'Slider Links'!$G$11:$K$11)/SQRT(SUMSQ('Slider Links'!$G$3:$K$3)*SUMSQ('Slider Links'!$G$11:$K$11)),0) -> 0.30709337 | L3: =IFERROR(SUMPRODUCT('Slider Links'!$G$3:$K$3,'Slider Links'!$G$12:$K$12)/SQRT(SUMSQ('Slider Links'!$G$3:$K$3)*SUMSQ('Slider Links'!$G$12:$K$12)),0) -> -0.55172414 | M3: =IFERROR(SUMPRODUCT('Slider Links'!$G$3:$K$3,'Slider Links'!$G$13:$K$13)/SQRT(SUMSQ('Slider Links'!$G$3:$K$3)*SUMSQ('Slider Links'!$G$13:$K$13)),0) -> 0 | N3: =IFERROR(SUMPRODUCT('Slider Links'!$G$3:$K$3,'Slider Links'!$G$14:$K$14)/SQRT(SUMSQ('Slider Links'!$G$3:$K$3)*SUMSQ('Slider Links'!$G$14:$K$14)),0) -> 0.7832934 | O3: =IFERROR(SUMPRODUCT('Slider Links'!$G$3:$K$3,'Slider Links'!$G$15:$K$15)/SQRT(SUMSQ('Slider Links'!$G$3:$K$3)*SUMSQ('Slider Links'!$G$15:$K$15)),0) -> -0.11397885 | P3: =IFERROR(SUMPRODUCT('Slider Links'!$G$3:$K$3,'Slider Links'!$G$16:$K$16)/SQRT(SUMSQ('Slider Links'!$G$3:$K$3)*SUMSQ('Slider Links'!$G$16:$K$16)),0) -> -0.20055097 | Q3: =IFERROR(SUMPRODUCT('Slider Links'!$G$3:$K$3,'Slider Links'!$G$17:$K$17)/SQRT(SUMSQ('Slider Links'!$G$3:$K$3)*SUMSQ('Slider Links'!$G$17:$K$17)),0) -> 0.11644109
A4: ='Slider Links'!A4 -> Earth | B4: =IFERROR(SUMPRODUCT('Slider Links'!$G$4:$K$4,'Slider Links'!$G$2:$K$2)/SQRT(SUMSQ('Slider Links'!$G$4:$K$4)*SUMSQ('Slider Links'!$G$2:$K$2)),0) -> 0.067346557 | C4: =IFERROR(SUMPRODUCT('Slider Links'!$G$4:$K$4,'Slider Links'!$G$3:$K$3)/SQRT(SUMSQ('Slider Links'!$G$4:$K$4)*SUMSQ('Slider Links'!$G$3:$K$3)),0) -> -0.24184306 | D4: =IFERROR(SUMPRODUCT('Slider Links'!$G$4:$K$4,'Slider Links'!$G$4:$K$4)/SQRT(SUMSQ('Slider Links'!$G$4:$K$4)*SUMSQ('Slider Links'!$G$4:$K$4)),0) -> 1 | E4: =IFERROR(SUMPRODUCT('Slider Links'!$G$4:$K$4,'Slider Links'!$G$5:$K$5)/SQRT(SUMSQ('Slider Links'!$G$4:$K$4)*SUMSQ('Slider Links'!$G$5:$K$5)),0) -> -0.27235239 | F4: =IFERROR(SUMPRODUCT('Slider Links'!$G$4:$K$4,'Slider Links'!$G$6:$K$6)/SQRT(SUMSQ('Slider Links'!$G$4:$K$4)*SUMSQ('Slider Links'!$G$6:$K$6)),0) -> -0.48701077 | G4: =IFERROR(SUMPRODUCT('Slider Links'!$G$4:$K$4,'Slider Links'!$G$7:$K$7)/SQRT(SUMSQ('Slider Links'!$G$4:$K$4)*SUMSQ('Slider Links'!$G$7:$K$7)),0) -> 0.36463019 | H4: =IFERROR(SUMPRODUCT('Slider Links'!$G$4:$K$4,'Slider Links'!$G$8:$K$8)/SQRT(SUMSQ('Slider Links'!$G$4:$K$4)*SUMSQ('Slider Links'!$G$8:$K$8)),0) -> -0.31872971 | I4: =IFERROR(SUMPRODUCT('Slider Links'!$G$4:$K$4,'Slider Links'!$G$9:$K$9)/SQRT(SUMSQ('Slider Links'!$G$4:$K$4)*SUMSQ('Slider Links'!$G$9:$K$9)),0) -> 0.88599367 | J4: =IFERROR(SUMPRODUCT('Slider Links'!$G$4:$K$4,'Slider Links'!$G$10:$K$10)/SQRT(SUMSQ('Slider Links'!$G$4:$K$4)*SUMSQ('Slider Links'!$G$10:$K$10)),0) -> 0.27151049 | K4: =IFERROR(SUMPRODUCT('Slider Links'!$G$4:$K$4,'Slider Links'!$G$11:$K$11)/SQRT(SUMSQ('Slider Links'!$G$4:$K$4)*SUMSQ('Slider Links'!$G$11:$K$11)),0) -> 0.3418704 | L4: =IFERROR(SUMPRODUCT('Slider Links'!$G$4:$K$4,'Slider Links'!$G$12:$K$12)/SQRT(SUMSQ('Slider Links'!$G$4:$K$4)*SUMSQ('Slider Links'!$G$12:$K$12)),0) -> 0.046065344 | M4: =IFERROR(SUMPRODUCT('Slider Links'!$G$4:$K$4,'Slider Links'!$G$13:$K$13)/SQRT(SUMSQ('Slider Links'!$G$4:$K$4)*SUMSQ('Slider Links'!$G$13:$K$13)),0) -> 0.53515468 | N4: =IFERROR(SUMPRODUCT('Slider Links'!$G$4:$K$4,'Slider Links'!$G$14:$K$14)/SQRT(SUMSQ('Slider Links'!$G$4:$K$4)*SUMSQ('Slider Links'!$G$14:$K$14)),0) -> -0.31532074 | O4: =IFERROR(SUMPRODUCT('Slider Links'!$G$4:$K$4,'Slider Links'!$G$15:$K$15)/SQRT(SUMSQ('Slider Links'!$G$4:$K$4)*SUMSQ('Slider Links'!$G$15:$K$15)),0) -> -0.78246663 | P4: =IFERROR(SUMPRODUCT('Slider Links'!$G$4:$K$4,'Slider Links'!$G$16:$K$16)/SQRT(SUMSQ('Slider Links'!$G$4:$K$4)*SUMSQ('Slider Links'!$G$16:$K$16)),0) -> 0.03721042 | Q4: =IFERROR(SUMPRODUCT('Slider Links'!$G$4:$K$4,'Slider Links'!$G$17:$K$17)/SQRT(SUMSQ('Slider Links'!$G$4:$K$4)*SUMSQ('Slider Links'!$G$17:$K$17)),0) -> -0.19444133
A5: ='Slider Links'!A5 -> Wind | B5: =IFERROR(SUMPRODUCT('Slider Links'!$G$5:$K$5,'Slider Links'!$G$2:$K$2)/SQRT(SUMSQ('Slider Links'!$G$5:$K$5)*SUMSQ('Slider Links'!$G$2:$K$2)),0) -> 0.869003 | C5: =IFERROR(SUMPRODUCT('Slider Links'!$G$5:$K$5,'Slider Links'!$G$3:$K$3)/SQRT(SUMSQ('Slider Links'!$G$5:$K$5)*SUMSQ('Slider Links'!$G$3:$K$3)),0) -> 0.21746411 | D5: =IFERROR(SUMPRODUCT('Slider Links'!$G$5:$K$5,'Slider Links'!$G$4:$K$4)/SQRT(SUMSQ('Slider Links'!$G$5:$K$5)*SUMSQ('Slider Links'!$G$4:$K$4)),0) -> -0.27235239 | E5: =IFERROR(SUMPRODUCT('Slider Links'!$G$5:$K$5,'Slider Links'!$G$5:$K$5)/SQRT(SUMSQ('Slider Links'!$G$5:$K$5)*SUMSQ('Slider Links'!$G$5:$K$5)),0) -> 1 | F5: =IFERROR(SUMPRODUCT('Slider Links'!$G$5:$K$5,'Slider Links'!$G$6:$K$6)/SQRT(SUMSQ('Slider Links'!$G$5:$K$5)*SUMSQ('Slider Links'!$G$6:$K$6)),0) -> 0.37282186 | G5: =IFERROR(SUMPRODUCT('Slider Links'!$G$5:$K$5,'Slider Links'!$G$7:$K$7)/SQRT(SUMSQ('Slider Links'!$G$5:$K$5)*SUMSQ('Slider Links'!$G$7:$K$7)),0) -> -0.351671 | H5: =IFERROR(SUMPRODUCT('Slider Links'!$G$5:$K$5,'Slider Links'!$G$8:$K$8)/SQRT(SUMSQ('Slider Links'!$G$5:$K$5)*SUMSQ('Slider Links'!$G$8:$K$8)),0) -> 0.037151881 | I5: =IFERROR(SUMPRODUCT('Slider Links'!$G$5:$K$5,'Slider Links'!$G$9:$K$9)/SQRT(SUMSQ('Slider Links'!$G$5:$K$5)*SUMSQ('Slider Links'!$G$9:$K$9)),0) -> -0.24603392 | J5: =IFERROR(SUMPRODUCT('Slider Links'!$G$5:$K$5,'Slider Links'!$G$10:$K$10)/SQRT(SUMSQ('Slider Links'!$G$5:$K$5)*SUMSQ('Slider Links'!$G$10:$K$10)),0) -> 0.7801895 | K5: =IFERROR(SUMPRODUCT('Slider Links'!$G$5:$K$5,'Slider Links'!$G$11:$K$11)/SQRT(SUMSQ('Slider Links'!$G$5:$K$5)*SUMSQ('Slider Links'!$G$11:$K$11)),0) -> 0.34583425 | L5: =IFERROR(SUMPRODUCT('Slider Links'!$G$5:$K$5,'Slider Links'!$G$12:$K$12)/SQRT(SUMSQ('Slider Links'!$G$5:$K$5)*SUMSQ('Slider Links'!$G$12:$K$12)),0) -> -0.32619617 | M5: =IFERROR(SUMPRODUCT('Slider Links'!$G$5:$K$5,'Slider Links'!$G$13:$K$13)/SQRT(SUMSQ('Slider Links'!$G$5:$K$5)*SUMSQ('Slider Links'!$G$13:$K$13)),0) -> 0.2296677 | N5: =IFERROR(SUMPRODUCT('Slider Links'!$G$5:$K$5,'Slider Links'!$G$14:$K$14)/SQRT(SUMSQ('Slider Links'!$G$5:$K$5)*SUMSQ('Slider Links'!$G$14:$K$14)),0) -> 0.34916797 | O5: =IFERROR(SUMPRODUCT('Slider Links'!$G$5:$K$5,'Slider Links'!$G$15:$K$15)/SQRT(SUMSQ('Slider Links'!$G$5:$K$5)*SUMSQ('Slider Links'!$G$15:$K$15)),0) -> 0.066555833 | P5: =IFERROR(SUMPRODUCT('Slider Links'!$G$5:$K$5,'Slider Links'!$G$16:$K$16)/SQRT(SUMSQ('Slider Links'!$G$5:$K$5)*SUMSQ('Slider Links'!$G$16:$K$16)),0) -> 0.23421602 | Q5: =IFERROR(SUMPRODUCT('Slider Links'!$G$5:$K$5,'Slider Links'!$G$17:$K$17)/SQRT(SUMSQ('Slider Links'!$G$5:$K$5)*SUMSQ('Slider Links'!$G$17:$K$17)),0) -> 0.28797293
A6: ='Slider Links'!A6 -> Lightning | B6: =IFERROR(SUMPRODUCT('Slider Links'!$G$6:$K$6,'Slider Links'!$G$2:$K$2)/SQRT(SUMSQ('Slider Links'!$G$6:$K$6)*SUMSQ('Slider Links'!$G$2:$K$2)),0) -> 0.055314225 | C6: =IFERROR(SUMPRODUCT('Slider Links'!$G$6:$K$6,'Slider Links'!$G$3:$K$3)/SQRT(SUMSQ('Slider Links'!$G$6:$K$6)*SUMSQ('Slider Links'!$G$3:$K$3)),0) -> 0.92223239 | D6: =IFERROR(SUMPRODUCT('Slider Links'!$G$6:$K$6,'Slider Links'!$G$4:$K$4)/SQRT(SUMSQ('Slider Links'!$G$6:$K$6)*SUMSQ('Slider Links'!$G$4:$K$4)),0) -> -0.48701077 | E6: =IFERROR(SUMPRODUCT('Slider Links'!$G$6:$K$6,'Slider Links'!$G$5:$K$5)/SQRT(SUMSQ('Slider Links'!$G$6:$K$6)*SUMSQ('Slider Links'!$G$5:$K$5)),0) -> 0.37282186 | F6: =IFERROR(SUMPRODUCT('Slider Links'!$G$6:$K$6,'Slider Links'!$G$6:$K$6)/SQRT(SUMSQ('Slider Links'!$G$6:$K$6)*SUMSQ('Slider Links'!$G$6:$K$6)),0) -> 1 | G6: =IFERROR(SUMPRODUCT('Slider Links'!$G$6:$K$6,'Slider Links'!$G$7:$K$7)/SQRT(SUMSQ('Slider Links'!$G$6:$K$6)*SUMSQ('Slider Links'!$G$7:$K$7)),0) -> -0.64405224 | H6: =IFERROR(SUMPRODUCT('Slider Links'!$G$6:$K$6,'Slider Links'!$G$8:$K$8)/SQRT(SUMSQ('Slider Links'!$G$6:$K$6)*SUMSQ('Slider Links'!$G$8:$K$8)),0) -> -0.55750409 | I6: =IFERROR(SUMPRODUCT('Slider Links'!$G$6:$K$6,'Slider Links'!$G$9:$K$9)/SQRT(SUMSQ('Slider Links'!$G$6:$K$6)*SUMSQ('Slider Links'!$G$9:$K$9)),0) -> -0.2568351 | J6: =IFERROR(SUMPRODUCT('Slider Links'!$G$6:$K$6,'Slider Links'!$G$10:$K$10)/SQRT(SUMSQ('Slider Links'!$G$6:$K$6)*SUMSQ('Slider Links'!$G$10:$K$10)),0) -> 0.16967516 | K6: =IFERROR(SUMPRODUCT('Slider Links'!$G$6:$K$6,'Slider Links'!$G$11:$K$11)/SQRT(SUMSQ('Slider Links'!$G$6:$K$6)*SUMSQ('Slider Links'!$G$11:$K$11)),0) -> 0.23399236 | L6: =IFERROR(SUMPRODUCT('Slider Links'!$G$6:$K$6,'Slider Links'!$G$12:$K$12)/SQRT(SUMSQ('Slider Links'!$G$6:$K$6)*SUMSQ('Slider Links'!$G$12:$K$12)),0) -> -0.53599831 | M6: =IFERROR(SUMPRODUCT('Slider Links'!$G$6:$K$6,'Slider Links'!$G$13:$K$13)/SQRT(SUMSQ('Slider Links'!$G$6:$K$6)*SUMSQ('Slider Links'!$G$13:$K$13)),0) -> -0.066597331 | N6: =IFERROR(SUMPRODUCT('Slider Links'!$G$6:$K$6,'Slider Links'!$G$14:$K$14)/SQRT(SUMSQ('Slider Links'!$G$6:$K$6)*SUMSQ('Slider Links'!$G$14:$K$14)),0) -> 0.91124216 | O6: =IFERROR(SUMPRODUCT('Slider Links'!$G$6:$K$6,'Slider Links'!$G$15:$K$15)/SQRT(SUMSQ('Slider Links'!$G$6:$K$6)*SUMSQ('Slider Links'!$G$15:$K$15)),0) -> -0.014474524 | P6: =IFERROR(SUMPRODUCT('Slider Links'!$G$6:$K$6,'Slider Links'!$G$16:$K$16)/SQRT(SUMSQ('Slider Links'!$G$6:$K$6)*SUMSQ('Slider Links'!$G$16:$K$16)),0) -> -0.26317534 | Q6: =IFERROR(SUMPRODUCT('Slider Links'!$G$6:$K$6,'Slider Links'!$G$17:$K$17)/SQRT(SUMSQ('Slider Links'!$G$6:$K$6)*SUMSQ('Slider Links'!$G$17:$K$17)),0) -> 0.1017708
A7: ='Slider Links'!A7 -> Ice | B7: =IFERROR(SUMPRODUCT('Slider Links'!$G$7:$K$7,'Slider Links'!$G$2:$K$2)/SQRT(SUMSQ('Slider Links'!$G$7:$K$7)*SUMSQ('Slider Links'!$G$2:$K$2)),0) -> -0.024715017 | C7: =IFERROR(SUMPRODUCT('Slider Links'!$G$7:$K$7,'Slider Links'!$G$3:$K$3)/SQRT(SUMSQ('Slider Links'!$G$7:$K$7)*SUMSQ('Slider Links'!$G$3:$K$3)),0) -> -0.767777 | D7: =IFERROR(SUMPRODUCT('Slider Links'!$G$7:$K$7,'Slider Links'!$G$4:$K$4)/SQRT(SUMSQ('Slider Links'!$G$7:$K$7)*SUMSQ('Slider Links'!$G$4:$K$4)),0) -> 0.36463019 | E7: =IFERROR(SUMPRODUCT('Slider Links'!$G$7:$K$7,'Slider Links'!$G$5:$K$5)/SQRT(SUMSQ('Slider Links'!$G$7:$K$7)*SUMSQ('Slider Links'!$G$5:$K$5)),0) -> -0.351671 | F7: =IFERROR(SUMPRODUCT('Slider Links'!$G$7:$K$7,'Slider Links'!$G$6:$K$6)/SQRT(SUMSQ('Slider Links'!$G$7:$K$7)*SUMSQ('Slider Links'!$G$6:$K$6)),0) -> -0.64405224 | G7: =IFERROR(SUMPRODUCT('Slider Links'!$G$7:$K$7,'Slider Links'!$G$7:$K$7)/SQRT(SUMSQ('Slider Links'!$G$7:$K$7)*SUMSQ('Slider Links'!$G$7:$K$7)),0) -> 1 | H7: =IFERROR(SUMPRODUCT('Slider Links'!$G$7:$K$7,'Slider Links'!$G$8:$K$8)/SQRT(SUMSQ('Slider Links'!$G$7:$K$7)*SUMSQ('Slider Links'!$G$8:$K$8)),0) -> 0.021660791 | I7: =IFERROR(SUMPRODUCT('Slider Links'!$G$7:$K$7,'Slider Links'!$G$9:$K$9)/SQRT(SUMSQ('Slider Links'!$G$7:$K$7)*SUMSQ('Slider Links'!$G$9:$K$9)),0) -> 0.45265187 | J7: =IFERROR(SUMPRODUCT('Slider Links'!$G$7:$K$7,'Slider Links'!$G$10:$K$10)/SQRT(SUMSQ('Slider Links'!$G$7:$K$7)*SUMSQ('Slider Links'!$G$10:$K$10)),0) -> -0.42599556 | K7: =IFERROR(SUMPRODUCT('Slider Links'!$G$7:$K$7,'Slider Links'!$G$11:$K$11)/SQRT(SUMSQ('Slider Links'!$G$7:$K$7)*SUMSQ('Slider Links'!$G$11:$K$11)),0) -> -0.37339436 | L7: =IFERROR(SUMPRODUCT('Slider Links'!$G$7:$K$7,'Slider Links'!$G$12:$K$12)/SQRT(SUMSQ('Slider Links'!$G$7:$K$7)*SUMSQ('Slider Links'!$G$12:$K$12)),0) -> 0.60576901 | M7: =IFERROR(SUMPRODUCT('Slider Links'!$G$7:$K$7,'Slider Links'!$G$13:$K$13)/SQRT(SUMSQ('Slider Links'!$G$7:$K$7)*SUMSQ('Slider Links'!$G$13:$K$13)),0) -> -0.066951981 | N7: =IFERROR(SUMPRODUCT('Slider Links'!$G$7:$K$7,'Slider Links'!$G$14:$K$14)/SQRT(SUMSQ('Slider Links'!$G$7:$K$7)*SUMSQ('Slider Links'!$G$14:$K$14)),0) -> -0.42143932 | O7: =IFERROR(SUMPRODUCT('Slider Links'!$G$7:$K$7,'Slider Links'!$G$15:$K$15)/SQRT(SUMSQ('Slider Links'!$G$7:$K$7)*SUMSQ('Slider Links'!$G$15:$K$15)),0) -> -0.36217328 | P7: =IFERROR(SUMPRODUCT('Slider Links'!$G$7:$K$7,'Slider Links'!$G$16:$K$16)/SQRT(SUMSQ('Slider Links'!$G$7:$K$7)*SUMSQ('Slider Links'!$G$16:$K$16)),0) -> 0.083450757 | Q7: =IFERROR(SUMPRODUCT('Slider Links'!$G$7:$K$7,'Slider Links'!$G$17:$K$17)/SQRT(SUMSQ('Slider Links'!$G$7:$K$7)*SUMSQ('Slider Links'!$G$17:$K$17)),0) -> -0.083948933
A8: ='Slider Links'!A8 -> Dark | B8: =IFERROR(SUMPRODUCT('Slider Links'!$G$8:$K$8,'Slider Links'!$G$2:$K$2)/SQRT(SUMSQ('Slider Links'!$G$8:$K$8)*SUMSQ('Slider Links'!$G$2:$K$2)),0) -> -0.05787694 | C8: =IFERROR(SUMPRODUCT('Slider Links'!$G$8:$K$8,'Slider Links'!$G$3:$K$3)/SQRT(SUMSQ('Slider Links'!$G$8:$K$8)*SUMSQ('Slider Links'!$G$3:$K$3)),0) -> -0.57261336 | D8: =IFERROR(SUMPRODUCT('Slider Links'!$G$8:$K$8,'Slider Links'!$G$4:$K$4)/SQRT(SUMSQ('Slider Links'!$G$8:$K$8)*SUMSQ('Slider Links'!$G$4:$K$4)),0) -> -0.31872971 | E8: =IFERROR(SUMPRODUCT('Slider Links'!$G$8:$K$8,'Slider Links'!$G$5:$K$5)/SQRT(SUMSQ('Slider Links'!$G$8:$K$8)*SUMSQ('Slider Links'!$G$5:$K$5)),0) -> 0.037151881 | F8: =IFERROR(SUMPRODUCT('Slider Links'!$G$8:$K$8,'Slider Links'!$G$6:$K$6)/SQRT(SUMSQ('Slider Links'!$G$8:$K$8)*SUMSQ('Slider Links'!$G$6:$K$6)),0) -> -0.55750409 | G8: =IFERROR(SUMPRODUCT('Slider Links'!$G$8:$K$8,'Slider Links'!$G$7:$K$7)/SQRT(SUMSQ('Slider Links'!$G$8:$K$8)*SUMSQ('Slider Links'!$G$7:$K$7)),0) -> 0.021660791 | H8: =IFERROR(SUMPRODUCT('Slider Links'!$G$8:$K$8,'Slider Links'!$G$8:$K$8)/SQRT(SUMSQ('Slider Links'!$G$8:$K$8)*SUMSQ('Slider Links'!$G$8:$K$8)),0) -> 1 | I8: =IFERROR(SUMPRODUCT('Slider Links'!$G$8:$K$8,'Slider Links'!$G$9:$K$9)/SQRT(SUMSQ('Slider Links'!$G$8:$K$8)*SUMSQ('Slider Links'!$G$9:$K$9)),0) -> -0.499078 | J8: =IFERROR(SUMPRODUCT('Slider Links'!$G$8:$K$8,'Slider Links'!$G$10:$K$10)/SQRT(SUMSQ('Slider Links'!$G$8:$K$8)*SUMSQ('Slider Links'!$G$10:$K$10)),0) -> -0.13043478 | K8: =IFERROR(SUMPRODUCT('Slider Links'!$G$8:$K$8,'Slider Links'!$G$11:$K$11)/SQRT(SUMSQ('Slider Links'!$G$8:$K$8)*SUMSQ('Slider Links'!$G$11:$K$11)),0) -> -0.48716823 | L8: =IFERROR(SUMPRODUCT('Slider Links'!$G$8:$K$8,'Slider Links'!$G$12:$K$12)/SQRT(SUMSQ('Slider Links'!$G$8:$K$8)*SUMSQ('Slider Links'!$G$12:$K$12)),0) -> 0.48778175 | M8: =IFERROR(SUMPRODUCT('Slider Links'!$G$8:$K$8,'Slider Links'!$G$13:$K$13)/SQRT(SUMSQ('Slider Links'!$G$8:$K$8)*SUMSQ('Slider Links'!$G$13:$K$13)),0) -> -0.41809677 | N8: =IFERROR(SUMPRODUCT('Slider Links'!$G$8:$K$8,'Slider Links'!$G$14:$K$14)/SQRT(SUMSQ('Slider Links'!$G$8:$K$8)*SUMSQ('Slider Links'!$G$14:$K$14)),0) -> -0.75990056 | O8: =IFERROR(SUMPRODUCT('Slider Links'!$G$8:$K$8,'Slider Links'!$G$15:$K$15)/SQRT(SUMSQ('Slider Links'!$G$8:$K$8)*SUMSQ('Slider Links'!$G$15:$K$15)),0) -> 0.76591088 | P8: =IFERROR(SUMPRODUCT('Slider Links'!$G$8:$K$8,'Slider Links'!$G$16:$K$16)/SQRT(SUMSQ('Slider Links'!$G$8:$K$8)*SUMSQ('Slider Links'!$G$16:$K$16)),0) -> 0.52535702 | Q8: =IFERROR(SUMPRODUCT('Slider Links'!$G$8:$K$8,'Slider Links'!$G$17:$K$17)/SQRT(SUMSQ('Slider Links'!$G$8:$K$8)*SUMSQ('Slider Links'!$G$17:$K$17)),0) -> 0.32998914
A9: ='Slider Links'!A9 -> Metal | B9: =IFERROR(SUMPRODUCT('Slider Links'!$G$9:$K$9,'Slider Links'!$G$2:$K$2)/SQRT(SUMSQ('Slider Links'!$G$9:$K$9)*SUMSQ('Slider Links'!$G$2:$K$2)),0) -> -0.021901895 | C9: =IFERROR(SUMPRODUCT('Slider Links'!$G$9:$K$9,'Slider Links'!$G$3:$K$3)/SQRT(SUMSQ('Slider Links'!$G$9:$K$9)*SUMSQ('Slider Links'!$G$3:$K$3)),0) -> -0.074904966 | D9: =IFERROR(SUMPRODUCT('Slider Links'!$G$9:$K$9,'Slider Links'!$G$4:$K$4)/SQRT(SUMSQ('Slider Links'!$G$9:$K$9)*SUMSQ('Slider Links'!$G$4:$K$4)),0) -> 0.88599367 | E9: =IFERROR(SUMPRODUCT('Slider Links'!$G$9:$K$9,'Slider Links'!$G$5:$K$5)/SQRT(SUMSQ('Slider Links'!$G$9:$K$9)*SUMSQ('Slider Links'!$G$5:$K$5)),0) -> -0.24603392 | F9: =IFERROR(SUMPRODUCT('Slider Links'!$G$9:$K$9,'Slider Links'!$G$6:$K$6)/SQRT(SUMSQ('Slider Links'!$G$9:$K$9)*SUMSQ('Slider Links'!$G$6:$K$6)),0) -> -0.2568351 | G9: =IFERROR(SUMPRODUCT('Slider Links'!$G$9:$K$9,'Slider Links'!$G$7:$K$7)/SQRT(SUMSQ('Slider Links'!$G$9:$K$9)*SUMSQ('Slider Links'!$G$7:$K$7)),0) -> 0.45265187 | H9: =IFERROR(SUMPRODUCT('Slider Links'!$G$9:$K$9,'Slider Links'!$G$8:$K$8)/SQRT(SUMSQ('Slider Links'!$G$9:$K$9)*SUMSQ('Slider Links'!$G$8:$K$8)),0) -> -0.499078 | I9: =IFERROR(SUMPRODUCT('Slider Links'!$G$9:$K$9,'Slider Links'!$G$9:$K$9)/SQRT(SUMSQ('Slider Links'!$G$9:$K$9)*SUMSQ('Slider Links'!$G$9:$K$9)),0) -> 1 | J9: =IFERROR(SUMPRODUCT('Slider Links'!$G$9:$K$9,'Slider Links'!$G$10:$K$10)/SQRT(SUMSQ('Slider Links'!$G$9:$K$9)*SUMSQ('Slider Links'!$G$10:$K$10)),0) -> 0.11517185 | K9: =IFERROR(SUMPRODUCT('Slider Links'!$G$9:$K$9,'Slider Links'!$G$11:$K$11)/SQRT(SUMSQ('Slider Links'!$G$9:$K$9)*SUMSQ('Slider Links'!$G$11:$K$11)),0) -> 0.09265024 | L9: =IFERROR(SUMPRODUCT('Slider Links'!$G$9:$K$9,'Slider Links'!$G$12:$K$12)/SQRT(SUMSQ('Slider Links'!$G$9:$K$9)*SUMSQ('Slider Links'!$G$12:$K$12)),0) -> 0.23719906 | M9: =IFERROR(SUMPRODUCT('Slider Links'!$G$9:$K$9,'Slider Links'!$G$13:$K$13)/SQRT(SUMSQ('Slider Links'!$G$9:$K$9)*SUMSQ('Slider Links'!$G$13:$K$13)),0) -> 0.25051013 | N9: =IFERROR(SUMPRODUCT('Slider Links'!$G$9:$K$9,'Slider Links'!$G$14:$K$14)/SQRT(SUMSQ('Slider Links'!$G$9:$K$9)*SUMSQ('Slider Links'!$G$14:$K$14)),0) -> -0.13293003 | O9: =IFERROR(SUMPRODUCT('Slider Links'!$G$9:$K$9,'Slider Links'!$G$15:$K$15)/SQRT(SUMSQ('Slider Links'!$G$9:$K$9)*SUMSQ('Slider Links'!$G$15:$K$15)),0) -> -0.91699956 | P9: =IFERROR(SUMPRODUCT('Slider Links'!$G$9:$K$9,'Slider Links'!$G$16:$K$16)/SQRT(SUMSQ('Slider Links'!$G$9:$K$9)*SUMSQ('Slider Links'!$G$16:$K$16)),0) -> 0.18824194 | Q9: =IFERROR(SUMPRODUCT('Slider Links'!$G$9:$K$9,'Slider Links'!$G$17:$K$17)/SQRT(SUMSQ('Slider Links'!$G$9:$K$9)*SUMSQ('Slider Links'!$G$17:$K$17)),0) -> 0.086792607
A10: ='Slider Links'!A10 -> Blood | B10: =IFERROR(SUMPRODUCT('Slider Links'!$G$10:$K$10,'Slider Links'!$G$2:$K$2)/SQRT(SUMSQ('Slider Links'!$G$10:$K$10)*SUMSQ('Slider Links'!$G$2:$K$2)),0) -> 0.8185453 | C10: =IFERROR(SUMPRODUCT('Slider Links'!$G$10:$K$10,'Slider Links'!$G$3:$K$3)/SQRT(SUMSQ('Slider Links'!$G$10:$K$10)*SUMSQ('Slider Links'!$G$3:$K$3)),0) -> 0.23328692 | D10: =IFERROR(SUMPRODUCT('Slider Links'!$G$10:$K$10,'Slider Links'!$G$4:$K$4)/SQRT(SUMSQ('Slider Links'!$G$10:$K$10)*SUMSQ('Slider Links'!$G$4:$K$4)),0) -> 0.27151049 | E10: =IFERROR(SUMPRODUCT('Slider Links'!$G$10:$K$10,'Slider Links'!$G$5:$K$5)/SQRT(SUMSQ('Slider Links'!$G$10:$K$10)*SUMSQ('Slider Links'!$G$5:$K$5)),0) -> 0.7801895 | F10: =IFERROR(SUMPRODUCT('Slider Links'!$G$10:$K$10,'Slider Links'!$G$6:$K$6)/SQRT(SUMSQ('Slider Links'!$G$10:$K$10)*SUMSQ('Slider Links'!$G$6:$K$6)),0) -> 0.16967516 | G10: =IFERROR(SUMPRODUCT('Slider Links'!$G$10:$K$10,'Slider Links'!$G$7:$K$7)/SQRT(SUMSQ('Slider Links'!$G$10:$K$10)*SUMSQ('Slider Links'!$G$7:$K$7)),0) -> -0.42599556 | H10: =IFERROR(SUMPRODUCT('Slider Links'!$G$10:$K$10,'Slider Links'!$G$8:$K$8)/SQRT(SUMSQ('Slider Links'!$G$10:$K$10)*SUMSQ('Slider Links'!$G$8:$K$8)),0) -> -0.13043478 | I10: =IFERROR(SUMPRODUCT('Slider Links'!$G$10:$K$10,'Slider Links'!$G$9:$K$9)/SQRT(SUMSQ('Slider Links'!$G$10:$K$10)*SUMSQ('Slider Links'!$G$9:$K$9)),0) -> 0.11517185 | J10: =IFERROR(SUMPRODUCT('Slider Links'!$G$10:$K$10,'Slider Links'!$G$10:$K$10)/SQRT(SUMSQ('Slider Links'!$G$10:$K$10)*SUMSQ('Slider Links'!$G$10:$K$10)),0) -> 1 | K10: =IFERROR(SUMPRODUCT('Slider Links'!$G$10:$K$10,'Slider Links'!$G$11:$K$11)/SQRT(SUMSQ('Slider Links'!$G$10:$K$10)*SUMSQ('Slider Links'!$G$11:$K$11)),0) -> 0.7270049 | L10: =IFERROR(SUMPRODUCT('Slider Links'!$G$10:$K$10,'Slider Links'!$G$12:$K$12)/SQRT(SUMSQ('Slider Links'!$G$10:$K$10)*SUMSQ('Slider Links'!$G$12:$K$12)),0) -> -0.54433615 | M10: =IFERROR(SUMPRODUCT('Slider Links'!$G$10:$K$10,'Slider Links'!$G$13:$K$13)/SQRT(SUMSQ('Slider Links'!$G$10:$K$10)*SUMSQ('Slider Links'!$G$13:$K$13)),0) -> 0.6570092 | N10: =IFERROR(SUMPRODUCT('Slider Links'!$G$10:$K$10,'Slider Links'!$G$14:$K$14)/SQRT(SUMSQ('Slider Links'!$G$10:$K$10)*SUMSQ('Slider Links'!$G$14:$K$14)),0) -> 0.2150662 | O10: =IFERROR(SUMPRODUCT('Slider Links'!$G$10:$K$10,'Slider Links'!$G$15:$K$15)/SQRT(SUMSQ('Slider Links'!$G$10:$K$10)*SUMSQ('Slider Links'!$G$15:$K$15)),0) -> -0.24664927 | P10: =IFERROR(SUMPRODUCT('Slider Links'!$G$10:$K$10,'Slider Links'!$G$16:$K$16)/SQRT(SUMSQ('Slider Links'!$G$10:$K$10)*SUMSQ('Slider Links'!$G$16:$K$16)),0) -> 0.083752569 | Q10: =IFERROR(SUMPRODUCT('Slider Links'!$G$10:$K$10,'Slider Links'!$G$17:$K$17)/SQRT(SUMSQ('Slider Links'!$G$10:$K$10)*SUMSQ('Slider Links'!$G$17:$K$17)),0) -> 0.0070210455
A11: ='Slider Links'!A11 -> Life | B11: =IFERROR(SUMPRODUCT('Slider Links'!$G$11:$K$11,'Slider Links'!$G$2:$K$2)/SQRT(SUMSQ('Slider Links'!$G$11:$K$11)*SUMSQ('Slider Links'!$G$2:$K$2)),0) -> 0.55586019 | C11: =IFERROR(SUMPRODUCT('Slider Links'!$G$11:$K$11,'Slider Links'!$G$3:$K$3)/SQRT(SUMSQ('Slider Links'!$G$11:$K$11)*SUMSQ('Slider Links'!$G$3:$K$3)),0) -> 0.30709337 | D11: =IFERROR(SUMPRODUCT('Slider Links'!$G$11:$K$11,'Slider Links'!$G$4:$K$4)/SQRT(SUMSQ('Slider Links'!$G$11:$K$11)*SUMSQ('Slider Links'!$G$4:$K$4)),0) -> 0.3418704 | E11: =IFERROR(SUMPRODUCT('Slider Links'!$G$11:$K$11,'Slider Links'!$G$5:$K$5)/SQRT(SUMSQ('Slider Links'!$G$11:$K$11)*SUMSQ('Slider Links'!$G$5:$K$5)),0) -> 0.34583425 | F11: =IFERROR(SUMPRODUCT('Slider Links'!$G$11:$K$11,'Slider Links'!$G$6:$K$6)/SQRT(SUMSQ('Slider Links'!$G$11:$K$11)*SUMSQ('Slider Links'!$G$6:$K$6)),0) -> 0.23399236 | G11: =IFERROR(SUMPRODUCT('Slider Links'!$G$11:$K$11,'Slider Links'!$G$7:$K$7)/SQRT(SUMSQ('Slider Links'!$G$11:$K$11)*SUMSQ('Slider Links'!$G$7:$K$7)),0) -> -0.37339436 | H11: =IFERROR(SUMPRODUCT('Slider Links'!$G$11:$K$11,'Slider Links'!$G$8:$K$8)/SQRT(SUMSQ('Slider Links'!$G$11:$K$11)*SUMSQ('Slider Links'!$G$8:$K$8)),0) -> -0.48716823 | I11: =IFERROR(SUMPRODUCT('Slider Links'!$G$11:$K$11,'Slider Links'!$G$9:$K$9)/SQRT(SUMSQ('Slider Links'!$G$11:$K$11)*SUMSQ('Slider Links'!$G$9:$K$9)),0) -> 0.09265024 | J11: =IFERROR(SUMPRODUCT('Slider Links'!$G$11:$K$11,'Slider Links'!$G$10:$K$10)/SQRT(SUMSQ('Slider Links'!$G$11:$K$11)*SUMSQ('Slider Links'!$G$10:$K$10)),0) -> 0.7270049 | K11: =IFERROR(SUMPRODUCT('Slider Links'!$G$11:$K$11,'Slider Links'!$G$11:$K$11)/SQRT(SUMSQ('Slider Links'!$G$11:$K$11)*SUMSQ('Slider Links'!$G$11:$K$11)),0) -> 1 | L11: =IFERROR(SUMPRODUCT('Slider Links'!$G$11:$K$11,'Slider Links'!$G$12:$K$12)/SQRT(SUMSQ('Slider Links'!$G$11:$K$11)*SUMSQ('Slider Links'!$G$12:$K$12)),0) -> -0.89934486 | M11: =IFERROR(SUMPRODUCT('Slider Links'!$G$11:$K$11,'Slider Links'!$G$13:$K$13)/SQRT(SUMSQ('Slider Links'!$G$11:$K$11)*SUMSQ('Slider Links'!$G$13:$K$13)),0) -> 0.94209196 | N11: =IFERROR(SUMPRODUCT('Slider Links'!$G$11:$K$11,'Slider Links'!$G$14:$K$14)/SQRT(SUMSQ('Slider Links'!$G$11:$K$11)*SUMSQ('Slider Links'!$G$14:$K$14)),0) -> 0.45971352 | O11: =IFERROR(SUMPRODUCT('Slider Links'!$G$11:$K$11,'Slider Links'!$G$15:$K$15)/SQRT(SUMSQ('Slider Links'!$G$11:$K$11)*SUMSQ('Slider Links'!$G$15:$K$15)),0) -> -0.34909551 | P11: =IFERROR(SUMPRODUCT('Slider Links'!$G$11:$K$11,'Slider Links'!$G$16:$K$16)/SQRT(SUMSQ('Slider Links'!$G$11:$K$11)*SUMSQ('Slider Links'!$G$16:$K$16)),0) -> -0.59849942 | Q11: =IFERROR(SUMPRODUCT('Slider Links'!$G$11:$K$11,'Slider Links'!$G$17:$K$17)/SQRT(SUMSQ('Slider Links'!$G$11:$K$11)*SUMSQ('Slider Links'!$G$17:$K$17)),0) -> -0.63904163
A12: ='Slider Links'!A12 -> Death | B12: =IFERROR(SUMPRODUCT('Slider Links'!$G$12:$K$12,'Slider Links'!$G$2:$K$2)/SQRT(SUMSQ('Slider Links'!$G$12:$K$12)*SUMSQ('Slider Links'!$G$2:$K$2)),0) -> -0.37910623 | C12: =IFERROR(SUMPRODUCT('Slider Links'!$G$12:$K$12,'Slider Links'!$G$3:$K$3)/SQRT(SUMSQ('Slider Links'!$G$12:$K$12)*SUMSQ('Slider Links'!$G$3:$K$3)),0) -> -0.55172414 | D12: =IFERROR(SUMPRODUCT('Slider Links'!$G$12:$K$12,'Slider Links'!$G$4:$K$4)/SQRT(SUMSQ('Slider Links'!$G$12:$K$12)*SUMSQ('Slider Links'!$G$4:$K$4)),0) -> 0.046065344 | E12: =IFERROR(SUMPRODUCT('Slider Links'!$G$12:$K$12,'Slider Links'!$G$5:$K$5)/SQRT(SUMSQ('Slider Links'!$G$12:$K$12)*SUMSQ('Slider Links'!$G$5:$K$5)),0) -> -0.32619617 | F12: =IFERROR(SUMPRODUCT('Slider Links'!$G$12:$K$12,'Slider Links'!$G$6:$K$6)/SQRT(SUMSQ('Slider Links'!$G$12:$K$12)*SUMSQ('Slider Links'!$G$6:$K$6)),0) -> -0.53599831 | G12: =IFERROR(SUMPRODUCT('Slider Links'!$G$12:$K$12,'Slider Links'!$G$7:$K$7)/SQRT(SUMSQ('Slider Links'!$G$12:$K$12)*SUMSQ('Slider Links'!$G$7:$K$7)),0) -> 0.60576901 | H12: =IFERROR(SUMPRODUCT('Slider Links'!$G$12:$K$12,'Slider Links'!$G$8:$K$8)/SQRT(SUMSQ('Slider Links'!$G$12:$K$12)*SUMSQ('Slider Links'!$G$8:$K$8)),0) -> 0.48778175 | I12: =IFERROR(SUMPRODUCT('Slider Links'!$G$12:$K$12,'Slider Links'!$G$9:$K$9)/SQRT(SUMSQ('Slider Links'!$G$12:$K$12)*SUMSQ('Slider Links'!$G$9:$K$9)),0) -> 0.23719906 | J12: =IFERROR(SUMPRODUCT('Slider Links'!$G$12:$K$12,'Slider Links'!$G$10:$K$10)/SQRT(SUMSQ('Slider Links'!$G$12:$K$12)*SUMSQ('Slider Links'!$G$10:$K$10)),0) -> -0.54433615 | K12: =IFERROR(SUMPRODUCT('Slider Links'!$G$12:$K$12,'Slider Links'!$G$11:$K$11)/SQRT(SUMSQ('Slider Links'!$G$12:$K$12)*SUMSQ('Slider Links'!$G$11:$K$11)),0) -> -0.89934486 | L12: =IFERROR(SUMPRODUCT('Slider Links'!$G$12:$K$12,'Slider Links'!$G$12:$K$12)/SQRT(SUMSQ('Slider Links'!$G$12:$K$12)*SUMSQ('Slider Links'!$G$12:$K$12)),0) -> 1 | M12: =IFERROR(SUMPRODUCT('Slider Links'!$G$12:$K$12,'Slider Links'!$G$13:$K$13)/SQRT(SUMSQ('Slider Links'!$G$12:$K$12)*SUMSQ('Slider Links'!$G$13:$K$13)),0) -> -0.72835704 | N12: =IFERROR(SUMPRODUCT('Slider Links'!$G$12:$K$12,'Slider Links'!$G$14:$K$14)/SQRT(SUMSQ('Slider Links'!$G$12:$K$12)*SUMSQ('Slider Links'!$G$14:$K$14)),0) -> -0.68538172 | O12: =IFERROR(SUMPRODUCT('Slider Links'!$G$12:$K$12,'Slider Links'!$G$15:$K$15)/SQRT(SUMSQ('Slider Links'!$G$12:$K$12)*SUMSQ('Slider Links'!$G$15:$K$15)),0) -> 0.075985902 | P12: =IFERROR(SUMPRODUCT('Slider Links'!$G$12:$K$12,'Slider Links'!$G$16:$K$16)/SQRT(SUMSQ('Slider Links'!$G$12:$K$12)*SUMSQ('Slider Links'!$G$16:$K$16)),0) -> 0.72792573 | Q12: =IFERROR(SUMPRODUCT('Slider Links'!$G$12:$K$12,'Slider Links'!$G$17:$K$17)/SQRT(SUMSQ('Slider Links'!$G$12:$K$12)*SUMSQ('Slider Links'!$G$17:$K$17)),0) -> 0.63015177
A13: ='Slider Links'!A13 -> Nature | B13: =IFERROR(SUMPRODUCT('Slider Links'!$G$13:$K$13,'Slider Links'!$G$2:$K$2)/SQRT(SUMSQ('Slider Links'!$G$13:$K$13)*SUMSQ('Slider Links'!$G$2:$K$2)),0) -> 0.57927436 | C13: =IFERROR(SUMPRODUCT('Slider Links'!$G$13:$K$13,'Slider Links'!$G$3:$K$3)/SQRT(SUMSQ('Slider Links'!$G$13:$K$13)*SUMSQ('Slider Links'!$G$3:$K$3)),0) -> 0 | D13: =IFERROR(SUMPRODUCT('Slider Links'!$G$13:$K$13,'Slider Links'!$G$4:$K$4)/SQRT(SUMSQ('Slider Links'!$G$13:$K$13)*SUMSQ('Slider Links'!$G$4:$K$4)),0) -> 0.53515468 | E13: =IFERROR(SUMPRODUCT('Slider Links'!$G$13:$K$13,'Slider Links'!$G$5:$K$5)/SQRT(SUMSQ('Slider Links'!$G$13:$K$13)*SUMSQ('Slider Links'!$G$5:$K$5)),0) -> 0.2296677 | F13: =IFERROR(SUMPRODUCT('Slider Links'!$G$13:$K$13,'Slider Links'!$G$6:$K$6)/SQRT(SUMSQ('Slider Links'!$G$13:$K$13)*SUMSQ('Slider Links'!$G$6:$K$6)),0) -> -0.066597331 | G13: =IFERROR(SUMPRODUCT('Slider Links'!$G$13:$K$13,'Slider Links'!$G$7:$K$7)/SQRT(SUMSQ('Slider Links'!$G$13:$K$13)*SUMSQ('Slider Links'!$G$7:$K$7)),0) -> -0.066951981 | H13: =IFERROR(SUMPRODUCT('Slider Links'!$G$13:$K$13,'Slider Links'!$G$8:$K$8)/SQRT(SUMSQ('Slider Links'!$G$13:$K$13)*SUMSQ('Slider Links'!$G$8:$K$8)),0) -> -0.41809677 | I13: =IFERROR(SUMPRODUCT('Slider Links'!$G$13:$K$13,'Slider Links'!$G$9:$K$9)/SQRT(SUMSQ('Slider Links'!$G$13:$K$13)*SUMSQ('Slider Links'!$G$9:$K$9)),0) -> 0.25051013 | J13: =IFERROR(SUMPRODUCT('Slider Links'!$G$13:$K$13,'Slider Links'!$G$10:$K$10)/SQRT(SUMSQ('Slider Links'!$G$13:$K$13)*SUMSQ('Slider Links'!$G$10:$K$10)),0) -> 0.6570092 | K13: =IFERROR(SUMPRODUCT('Slider Links'!$G$13:$K$13,'Slider Links'!$G$11:$K$11)/SQRT(SUMSQ('Slider Links'!$G$13:$K$13)*SUMSQ('Slider Links'!$G$11:$K$11)),0) -> 0.94209196 | L13: =IFERROR(SUMPRODUCT('Slider Links'!$G$13:$K$13,'Slider Links'!$G$12:$K$12)/SQRT(SUMSQ('Slider Links'!$G$13:$K$13)*SUMSQ('Slider Links'!$G$12:$K$12)),0) -> -0.72835704 | M13: =IFERROR(SUMPRODUCT('Slider Links'!$G$13:$K$13,'Slider Links'!$G$13:$K$13)/SQRT(SUMSQ('Slider Links'!$G$13:$K$13)*SUMSQ('Slider Links'!$G$13:$K$13)),0) -> 1 | N13: =IFERROR(SUMPRODUCT('Slider Links'!$G$13:$K$13,'Slider Links'!$G$14:$K$14)/SQRT(SUMSQ('Slider Links'!$G$13:$K$13)*SUMSQ('Slider Links'!$G$14:$K$14)),0) -> 0.23635715 | O13: =IFERROR(SUMPRODUCT('Slider Links'!$G$13:$K$13,'Slider Links'!$G$15:$K$15)/SQRT(SUMSQ('Slider Links'!$G$13:$K$13)*SUMSQ('Slider Links'!$G$15:$K$15)),0) -> -0.45475032 | P13: =IFERROR(SUMPRODUCT('Slider Links'!$G$13:$K$13,'Slider Links'!$G$16:$K$16)/SQRT(SUMSQ('Slider Links'!$G$13:$K$13)*SUMSQ('Slider Links'!$G$16:$K$16)),0) -> -0.56481447 | Q13: =IFERROR(SUMPRODUCT('Slider Links'!$G$13:$K$13,'Slider Links'!$G$17:$K$17)/SQRT(SUMSQ('Slider Links'!$G$13:$K$13)*SUMSQ('Slider Links'!$G$17:$K$17)),0) -> -0.70891756
A14: ='Slider Links'!A14 -> Light | B14: =IFERROR(SUMPRODUCT('Slider Links'!$G$14:$K$14,'Slider Links'!$G$2:$K$2)/SQRT(SUMSQ('Slider Links'!$G$14:$K$14)*SUMSQ('Slider Links'!$G$2:$K$2)),0) -> 0.22085197 | C14: =IFERROR(SUMPRODUCT('Slider Links'!$G$14:$K$14,'Slider Links'!$G$3:$K$3)/SQRT(SUMSQ('Slider Links'!$G$14:$K$14)*SUMSQ('Slider Links'!$G$3:$K$3)),0) -> 0.7832934 | D14: =IFERROR(SUMPRODUCT('Slider Links'!$G$14:$K$14,'Slider Links'!$G$4:$K$4)/SQRT(SUMSQ('Slider Links'!$G$14:$K$14)*SUMSQ('Slider Links'!$G$4:$K$4)),0) -> -0.31532074 | E14: =IFERROR(SUMPRODUCT('Slider Links'!$G$14:$K$14,'Slider Links'!$G$5:$K$5)/SQRT(SUMSQ('Slider Links'!$G$14:$K$14)*SUMSQ('Slider Links'!$G$5:$K$5)),0) -> 0.34916797 | F14: =IFERROR(SUMPRODUCT('Slider Links'!$G$14:$K$14,'Slider Links'!$G$6:$K$6)/SQRT(SUMSQ('Slider Links'!$G$14:$K$14)*SUMSQ('Slider Links'!$G$6:$K$6)),0) -> 0.91124216 | G14: =IFERROR(SUMPRODUCT('Slider Links'!$G$14:$K$14,'Slider Links'!$G$7:$K$7)/SQRT(SUMSQ('Slider Links'!$G$14:$K$14)*SUMSQ('Slider Links'!$G$7:$K$7)),0) -> -0.42143932 | H14: =IFERROR(SUMPRODUCT('Slider Links'!$G$14:$K$14,'Slider Links'!$G$8:$K$8)/SQRT(SUMSQ('Slider Links'!$G$14:$K$14)*SUMSQ('Slider Links'!$G$8:$K$8)),0) -> -0.75990056 | I14: =IFERROR(SUMPRODUCT('Slider Links'!$G$14:$K$14,'Slider Links'!$G$9:$K$9)/SQRT(SUMSQ('Slider Links'!$G$14:$K$14)*SUMSQ('Slider Links'!$G$9:$K$9)),0) -> -0.13293003 | J14: =IFERROR(SUMPRODUCT('Slider Links'!$G$14:$K$14,'Slider Links'!$G$10:$K$10)/SQRT(SUMSQ('Slider Links'!$G$14:$K$14)*SUMSQ('Slider Links'!$G$10:$K$10)),0) -> 0.2150662 | K14: =IFERROR(SUMPRODUCT('Slider Links'!$G$14:$K$14,'Slider Links'!$G$11:$K$11)/SQRT(SUMSQ('Slider Links'!$G$14:$K$14)*SUMSQ('Slider Links'!$G$11:$K$11)),0) -> 0.45971352 | L14: =IFERROR(SUMPRODUCT('Slider Links'!$G$14:$K$14,'Slider Links'!$G$12:$K$12)/SQRT(SUMSQ('Slider Links'!$G$14:$K$14)*SUMSQ('Slider Links'!$G$12:$K$12)),0) -> -0.68538172 | M14: =IFERROR(SUMPRODUCT('Slider Links'!$G$14:$K$14,'Slider Links'!$G$13:$K$13)/SQRT(SUMSQ('Slider Links'!$G$14:$K$14)*SUMSQ('Slider Links'!$G$13:$K$13)),0) -> 0.23635715 | N14: =IFERROR(SUMPRODUCT('Slider Links'!$G$14:$K$14,'Slider Links'!$G$14:$K$14)/SQRT(SUMSQ('Slider Links'!$G$14:$K$14)*SUMSQ('Slider Links'!$G$14:$K$14)),0) -> 1 | O14: =IFERROR(SUMPRODUCT('Slider Links'!$G$14:$K$14,'Slider Links'!$G$15:$K$15)/SQRT(SUMSQ('Slider Links'!$G$14:$K$14)*SUMSQ('Slider Links'!$G$15:$K$15)),0) -> -0.23116854 | P14: =IFERROR(SUMPRODUCT('Slider Links'!$G$14:$K$14,'Slider Links'!$G$16:$K$16)/SQRT(SUMSQ('Slider Links'!$G$14:$K$14)*SUMSQ('Slider Links'!$G$16:$K$16)),0) -> -0.54233538 | Q14: =IFERROR(SUMPRODUCT('Slider Links'!$G$14:$K$14,'Slider Links'!$G$17:$K$17)/SQRT(SUMSQ('Slider Links'!$G$14:$K$14)*SUMSQ('Slider Links'!$G$17:$K$17)),0) -> -0.22227046
A15: ='Slider Links'!A15 -> Dream | B15: =IFERROR(SUMPRODUCT('Slider Links'!$G$15:$K$15,'Slider Links'!$G$2:$K$2)/SQRT(SUMSQ('Slider Links'!$G$15:$K$15)*SUMSQ('Slider Links'!$G$2:$K$2)),0) -> -0.17774365 | C15: =IFERROR(SUMPRODUCT('Slider Links'!$G$15:$K$15,'Slider Links'!$G$3:$K$3)/SQRT(SUMSQ('Slider Links'!$G$15:$K$15)*SUMSQ('Slider Links'!$G$3:$K$3)),0) -> -0.11397885 | D15: =IFERROR(SUMPRODUCT('Slider Links'!$G$15:$K$15,'Slider Links'!$G$4:$K$4)/SQRT(SUMSQ('Slider Links'!$G$15:$K$15)*SUMSQ('Slider Links'!$G$4:$K$4)),0) -> -0.78246663 | E15: =IFERROR(SUMPRODUCT('Slider Links'!$G$15:$K$15,'Slider Links'!$G$5:$K$5)/SQRT(SUMSQ('Slider Links'!$G$15:$K$15)*SUMSQ('Slider Links'!$G$5:$K$5)),0) -> 0.066555833 | F15: =IFERROR(SUMPRODUCT('Slider Links'!$G$15:$K$15,'Slider Links'!$G$6:$K$6)/SQRT(SUMSQ('Slider Links'!$G$15:$K$15)*SUMSQ('Slider Links'!$G$6:$K$6)),0) -> -0.014474524 | G15: =IFERROR(SUMPRODUCT('Slider Links'!$G$15:$K$15,'Slider Links'!$G$7:$K$7)/SQRT(SUMSQ('Slider Links'!$G$15:$K$15)*SUMSQ('Slider Links'!$G$7:$K$7)),0) -> -0.36217328 | H15: =IFERROR(SUMPRODUCT('Slider Links'!$G$15:$K$15,'Slider Links'!$G$8:$K$8)/SQRT(SUMSQ('Slider Links'!$G$15:$K$15)*SUMSQ('Slider Links'!$G$8:$K$8)),0) -> 0.76591088 | I15: =IFERROR(SUMPRODUCT('Slider Links'!$G$15:$K$15,'Slider Links'!$G$9:$K$9)/SQRT(SUMSQ('Slider Links'!$G$15:$K$15)*SUMSQ('Slider Links'!$G$9:$K$9)),0) -> -0.91699956 | J15: =IFERROR(SUMPRODUCT('Slider Links'!$G$15:$K$15,'Slider Links'!$G$10:$K$10)/SQRT(SUMSQ('Slider Links'!$G$15:$K$15)*SUMSQ('Slider Links'!$G$10:$K$10)),0) -> -0.24664927 | K15: =IFERROR(SUMPRODUCT('Slider Links'!$G$15:$K$15,'Slider Links'!$G$11:$K$11)/SQRT(SUMSQ('Slider Links'!$G$15:$K$15)*SUMSQ('Slider Links'!$G$11:$K$11)),0) -> -0.34909551 | L15: =IFERROR(SUMPRODUCT('Slider Links'!$G$15:$K$15,'Slider Links'!$G$12:$K$12)/SQRT(SUMSQ('Slider Links'!$G$15:$K$15)*SUMSQ('Slider Links'!$G$12:$K$12)),0) -> 0.075985902 | M15: =IFERROR(SUMPRODUCT('Slider Links'!$G$15:$K$15,'Slider Links'!$G$13:$K$13)/SQRT(SUMSQ('Slider Links'!$G$15:$K$15)*SUMSQ('Slider Links'!$G$13:$K$13)),0) -> -0.45475032 | N15: =IFERROR(SUMPRODUCT('Slider Links'!$G$15:$K$15,'Slider Links'!$G$14:$K$14)/SQRT(SUMSQ('Slider Links'!$G$15:$K$15)*SUMSQ('Slider Links'!$G$14:$K$14)),0) -> -0.23116854 | O15: =IFERROR(SUMPRODUCT('Slider Links'!$G$15:$K$15,'Slider Links'!$G$15:$K$15)/SQRT(SUMSQ('Slider Links'!$G$15:$K$15)*SUMSQ('Slider Links'!$G$15:$K$15)),0) -> 1 | P15: =IFERROR(SUMPRODUCT('Slider Links'!$G$15:$K$15,'Slider Links'!$G$16:$K$16)/SQRT(SUMSQ('Slider Links'!$G$15:$K$15)*SUMSQ('Slider Links'!$G$16:$K$16)),0) -> 0.095479208 | Q15: =IFERROR(SUMPRODUCT('Slider Links'!$G$15:$K$15,'Slider Links'!$G$17:$K$17)/SQRT(SUMSQ('Slider Links'!$G$15:$K$15)*SUMSQ('Slider Links'!$G$17:$K$17)),0) -> 0.11320083
A16: ='Slider Links'!A16 -> Poison | B16: =IFERROR(SUMPRODUCT('Slider Links'!$G$16:$K$16,'Slider Links'!$G$2:$K$2)/SQRT(SUMSQ('Slider Links'!$G$16:$K$16)*SUMSQ('Slider Links'!$G$2:$K$2)),0) -> 0.01737489 | C16: =IFERROR(SUMPRODUCT('Slider Links'!$G$16:$K$16,'Slider Links'!$G$3:$K$3)/SQRT(SUMSQ('Slider Links'!$G$16:$K$16)*SUMSQ('Slider Links'!$G$3:$K$3)),0) -> -0.20055097 | D16: =IFERROR(SUMPRODUCT('Slider Links'!$G$16:$K$16,'Slider Links'!$G$4:$K$4)/SQRT(SUMSQ('Slider Links'!$G$16:$K$16)*SUMSQ('Slider Links'!$G$4:$K$4)),0) -> 0.03721042 | E16: =IFERROR(SUMPRODUCT('Slider Links'!$G$16:$K$16,'Slider Links'!$G$5:$K$5)/SQRT(SUMSQ('Slider Links'!$G$16:$K$16)*SUMSQ('Slider Links'!$G$5:$K$5)),0) -> 0.23421602 | F16: =IFERROR(SUMPRODUCT('Slider Links'!$G$16:$K$16,'Slider Links'!$G$6:$K$6)/SQRT(SUMSQ('Slider Links'!$G$16:$K$16)*SUMSQ('Slider Links'!$G$6:$K$6)),0) -> -0.26317534 | G16: =IFERROR(SUMPRODUCT('Slider Links'!$G$16:$K$16,'Slider Links'!$G$7:$K$7)/SQRT(SUMSQ('Slider Links'!$G$16:$K$16)*SUMSQ('Slider Links'!$G$7:$K$7)),0) -> 0.083450757 | H16: =IFERROR(SUMPRODUCT('Slider Links'!$G$16:$K$16,'Slider Links'!$G$8:$K$8)/SQRT(SUMSQ('Slider Links'!$G$16:$K$16)*SUMSQ('Slider Links'!$G$8:$K$8)),0) -> 0.52535702 | I16: =IFERROR(SUMPRODUCT('Slider Links'!$G$16:$K$16,'Slider Links'!$G$9:$K$9)/SQRT(SUMSQ('Slider Links'!$G$16:$K$16)*SUMSQ('Slider Links'!$G$9:$K$9)),0) -> 0.18824194 | J16: =IFERROR(SUMPRODUCT('Slider Links'!$G$16:$K$16,'Slider Links'!$G$10:$K$10)/SQRT(SUMSQ('Slider Links'!$G$16:$K$16)*SUMSQ('Slider Links'!$G$10:$K$10)),0) -> 0.083752569 | K16: =IFERROR(SUMPRODUCT('Slider Links'!$G$16:$K$16,'Slider Links'!$G$11:$K$11)/SQRT(SUMSQ('Slider Links'!$G$16:$K$16)*SUMSQ('Slider Links'!$G$11:$K$11)),0) -> -0.59849942 | L16: =IFERROR(SUMPRODUCT('Slider Links'!$G$16:$K$16,'Slider Links'!$G$12:$K$12)/SQRT(SUMSQ('Slider Links'!$G$16:$K$16)*SUMSQ('Slider Links'!$G$12:$K$12)),0) -> 0.72792573 | M16: =IFERROR(SUMPRODUCT('Slider Links'!$G$16:$K$16,'Slider Links'!$G$13:$K$13)/SQRT(SUMSQ('Slider Links'!$G$16:$K$16)*SUMSQ('Slider Links'!$G$13:$K$13)),0) -> -0.56481447 | N16: =IFERROR(SUMPRODUCT('Slider Links'!$G$16:$K$16,'Slider Links'!$G$14:$K$14)/SQRT(SUMSQ('Slider Links'!$G$16:$K$16)*SUMSQ('Slider Links'!$G$14:$K$14)),0) -> -0.54233538 | O16: =IFERROR(SUMPRODUCT('Slider Links'!$G$16:$K$16,'Slider Links'!$G$15:$K$15)/SQRT(SUMSQ('Slider Links'!$G$16:$K$16)*SUMSQ('Slider Links'!$G$15:$K$15)),0) -> 0.095479208 | P16: =IFERROR(SUMPRODUCT('Slider Links'!$G$16:$K$16,'Slider Links'!$G$16:$K$16)/SQRT(SUMSQ('Slider Links'!$G$16:$K$16)*SUMSQ('Slider Links'!$G$16:$K$16)),0) -> 1 | Q16: =IFERROR(SUMPRODUCT('Slider Links'!$G$16:$K$16,'Slider Links'!$G$17:$K$17)/SQRT(SUMSQ('Slider Links'!$G$16:$K$16)*SUMSQ('Slider Links'!$G$17:$K$17)),0) -> 0.92213889
A17: ='Slider Links'!A17 -> Disease | B17: =IFERROR(SUMPRODUCT('Slider Links'!$G$17:$K$17,'Slider Links'!$G$2:$K$2)/SQRT(SUMSQ('Slider Links'!$G$17:$K$17)*SUMSQ('Slider Links'!$G$2:$K$2)),0) -> -0.064088246 | C17: =IFERROR(SUMPRODUCT('Slider Links'!$G$17:$K$17,'Slider Links'!$G$3:$K$3)/SQRT(SUMSQ('Slider Links'!$G$17:$K$17)*SUMSQ('Slider Links'!$G$3:$K$3)),0) -> 0.11644109 | D17: =IFERROR(SUMPRODUCT('Slider Links'!$G$17:$K$17,'Slider Links'!$G$4:$K$4)/SQRT(SUMSQ('Slider Links'!$G$17:$K$17)*SUMSQ('Slider Links'!$G$4:$K$4)),0) -> -0.19444133 | E17: =IFERROR(SUMPRODUCT('Slider Links'!$G$17:$K$17,'Slider Links'!$G$5:$K$5)/SQRT(SUMSQ('Slider Links'!$G$17:$K$17)*SUMSQ('Slider Links'!$G$5:$K$5)),0) -> 0.28797293 | F17: =IFERROR(SUMPRODUCT('Slider Links'!$G$17:$K$17,'Slider Links'!$G$6:$K$6)/SQRT(SUMSQ('Slider Links'!$G$17:$K$17)*SUMSQ('Slider Links'!$G$6:$K$6)),0) -> 0.1017708 | G17: =IFERROR(SUMPRODUCT('Slider Links'!$G$17:$K$17,'Slider Links'!$G$7:$K$7)/SQRT(SUMSQ('Slider Links'!$G$17:$K$17)*SUMSQ('Slider Links'!$G$7:$K$7)),0) -> -0.083948933 | H17: =IFERROR(SUMPRODUCT('Slider Links'!$G$17:$K$17,'Slider Links'!$G$8:$K$8)/SQRT(SUMSQ('Slider Links'!$G$17:$K$17)*SUMSQ('Slider Links'!$G$8:$K$8)),0) -> 0.32998914 | I17: =IFERROR(SUMPRODUCT('Slider Links'!$G$17:$K$17,'Slider Links'!$G$9:$K$9)/SQRT(SUMSQ('Slider Links'!$G$17:$K$17)*SUMSQ('Slider Links'!$G$9:$K$9)),0) -> 0.086792607 | J17: =IFERROR(SUMPRODUCT('Slider Links'!$G$17:$K$17,'Slider Links'!$G$10:$K$10)/SQRT(SUMSQ('Slider Links'!$G$17:$K$17)*SUMSQ('Slider Links'!$G$10:$K$10)),0) -> 0.0070210455 | K17: =IFERROR(SUMPRODUCT('Slider Links'!$G$17:$K$17,'Slider Links'!$G$11:$K$11)/SQRT(SUMSQ('Slider Links'!$G$17:$K$17)*SUMSQ('Slider Links'!$G$11:$K$11)),0) -> -0.63904163 | L17: =IFERROR(SUMPRODUCT('Slider Links'!$G$17:$K$17,'Slider Links'!$G$12:$K$12)/SQRT(SUMSQ('Slider Links'!$G$17:$K$17)*SUMSQ('Slider Links'!$G$12:$K$12)),0) -> 0.63015177 | M17: =IFERROR(SUMPRODUCT('Slider Links'!$G$17:$K$17,'Slider Links'!$G$13:$K$13)/SQRT(SUMSQ('Slider Links'!$G$17:$K$17)*SUMSQ('Slider Links'!$G$13:$K$13)),0) -> -0.70891756 | N17: =IFERROR(SUMPRODUCT('Slider Links'!$G$17:$K$17,'Slider Links'!$G$14:$K$14)/SQRT(SUMSQ('Slider Links'!$G$17:$K$17)*SUMSQ('Slider Links'!$G$14:$K$14)),0) -> -0.22227046 | O17: =IFERROR(SUMPRODUCT('Slider Links'!$G$17:$K$17,'Slider Links'!$G$15:$K$15)/SQRT(SUMSQ('Slider Links'!$G$17:$K$17)*SUMSQ('Slider Links'!$G$15:$K$15)),0) -> 0.11320083 | P17: =IFERROR(SUMPRODUCT('Slider Links'!$G$17:$K$17,'Slider Links'!$G$16:$K$16)/SQRT(SUMSQ('Slider Links'!$G$17:$K$17)*SUMSQ('Slider Links'!$G$16:$K$16)),0) -> 0.92213889 | Q17: =IFERROR(SUMPRODUCT('Slider Links'!$G$17:$K$17,'Slider Links'!$G$17:$K$17)/SQRT(SUMSQ('Slider Links'!$G$17:$K$17)*SUMSQ('Slider Links'!$G$17:$K$17)),0) -> 1
A19: Refuse below | B19: -0.7
A20: Weaken below | B20: 0
A21: Pairs that refuse | B21: =COUNTIF($B$2:$Q$17,"<"&$B$19)/2 -> 7
A22: Pairs weakened | B22: =(COUNTIF($B$2:$Q$17,"<"&$B$20)-COUNTIF($B$2:$Q$17,"<"&$B$19))/2 -> 50
A24: Each cell is how well two affinities line up (the cosine of their five positions): +1 the same way, -1 opposite. Red: they refuse to bond. Amber: they bond, weakened. Green: they bond, strengthened. Universal runes have no position and bond with anything. Move the sliders on the Affinities sheet; change the two thresholds in yellow.

Sheet Base Runes
A1: ID | B1: Affinity | C1: Pair | D1: Rune | E1: Character | F1: Opposite ID | G1: Opposite | H1: Opposite character | I1: As a skill (from the affinity sheet) | J1: Code point as first assigned | K1: Role | L1: Draw (-1 gives ... +1 takes) | M1: Valence | N1: Electronegativity | O1: Effect (game)
A2: WAT-1a | B2: Water | C2: 1 | D2: Flood | E2: ᚠ | F2: WAT-1b | G2: =IFERROR(INDEX($D:$D,MATCH($F2,$A:$A,0)),"") -> Drain | H2: =IFERROR(INDEX($E:$E,MATCH($F2,$A:$A,0)),"") -> ᚡ | I2: =Water!$E$6 -> fill an area with water; the ground turns Wet | J2: U+16A0 | K2: Branch | L2: -0.6 | M2: =IFERROR(INDEX('Bond Rules'!$B$4:$B$7,MATCH(K2,'Bond Rules'!$A$4:$A$7,0)),"") -> 3 | N2: =IFERROR(ROUND('Bond Rules'!$B$9+L2*INDEX('Bond Rules'!$C$4:$C$7,MATCH(K2,'Bond Rules'!$A$4:$A$7,0)),2),"") -> 2.08 | O2: reach x1.2; status soaked
A3: WAT-1b | B3: Water | C3: 1 | D3: Drain | E3: ᚡ | F3: WAT-1a | G3: =IFERROR(INDEX($D:$D,MATCH($F3,$A:$A,0)),"") -> Flood | H3: =IFERROR(INDEX($E:$E,MATCH($F3,$A:$A,0)),"") -> ᚠ | I3: =Water!$E$7 -> empty the water from an area or a target, and draw it in | J3: U+16A1 | K3: Link | L3: 0.6 | M3: =IFERROR(INDEX('Bond Rules'!$B$4:$B$7,MATCH(K3,'Bond Rules'!$A$4:$A$7,0)),"") -> 2 | N3: =IFERROR(ROUND('Bond Rules'!$B$9+L3*INDEX('Bond Rules'!$C$4:$C$7,MATCH(K3,'Bond Rules'!$A$4:$A$7,0)),2),"") -> 3.1 | O3: bonus soaked +0.25; cost x0.9
A4: WAT-2a | B4: Water | C4: 2 | D4: Surge | E4: ᚢ | F4: WAT-2b | G4: =IFERROR(INDEX($D:$D,MATCH($F4,$A:$A,0)),"") -> Ebb | H4: =IFERROR(INDEX($E:$E,MATCH($F4,$A:$A,0)),"") -> ᚣ | I4: =Water!$E$8 -> push bodies away | J4: U+16A2 | K4: Link | L4: -0.6 | M4: =IFERROR(INDEX('Bond Rules'!$B$4:$B$7,MATCH(K4,'Bond Rules'!$A$4:$A$7,0)),"") -> 2 | N4: =IFERROR(ROUND('Bond Rules'!$B$9+L4*INDEX('Bond Rules'!$C$4:$C$7,MATCH(K4,'Bond Rules'!$A$4:$A$7,0)),2),"") -> 1.9 | O4: shove +1.5
A5: WAT-2b | B5: Water | C5: 2 | D5: Ebb | E5: ᚣ | F5: WAT-2a | G5: =IFERROR(INDEX($D:$D,MATCH($F5,$A:$A,0)),"") -> Surge | H5: =IFERROR(INDEX($E:$E,MATCH($F5,$A:$A,0)),"") -> ᚢ | I5: =Water!$E$9 -> draw bodies in | J5: U+16A3 | K5: Link | L5: 0.6 | M5: =IFERROR(INDEX('Bond Rules'!$B$4:$B$7,MATCH(K5,'Bond Rules'!$A$4:$A$7,0)),"") -> 2 | N5: =IFERROR(ROUND('Bond Rules'!$B$9+L5*INDEX('Bond Rules'!$C$4:$C$7,MATCH(K5,'Bond Rules'!$A$4:$A$7,0)),2),"") -> 3.1 | O5: pull +1.5
A6: WAT-3a | B6: Water | C6: 3 | D6: Soak | E6: ᚤ | F6: WAT-3b | G6: =IFERROR(INDEX($D:$D,MATCH($F6,$A:$A,0)),"") -> Dry | H6: =IFERROR(INDEX($E:$E,MATCH($F6,$A:$A,0)),"") -> ᚥ | I6: =Water!$E$10 -> saturate a target | J6: U+16A4 | K6: Link | L6: -0.5 | M6: =IFERROR(INDEX('Bond Rules'!$B$4:$B$7,MATCH(K6,'Bond Rules'!$A$4:$A$7,0)),"") -> 2 | N6: =IFERROR(ROUND('Bond Rules'!$B$9+L6*INDEX('Bond Rules'!$C$4:$C$7,MATCH(K6,'Bond Rules'!$A$4:$A$7,0)),2),"") -> 2 | O6: status soaked
A7: WAT-3b | B7: Water | C7: 3 | D7: Dry | E7: ᚥ | F7: WAT-3a | G7: =IFERROR(INDEX($D:$D,MATCH($F7,$A:$A,0)),"") -> Soak | H7: =IFERROR(INDEX($E:$E,MATCH($F7,$A:$A,0)),"") -> ᚤ | I7: =Water!$E$11 -> pull the water out of a body: damage by how wet it is | J7: U+16A5 | K7: Cap | L7: 0.8 | M7: =IFERROR(INDEX('Bond Rules'!$B$4:$B$7,MATCH(K7,'Bond Rules'!$A$4:$A$7,0)),"") -> 1 | N7: =IFERROR(ROUND('Bond Rules'!$B$9+L7*INDEX('Bond Rules'!$C$4:$C$7,MATCH(K7,'Bond Rules'!$A$4:$A$7,0)),2),"") -> 3.7 | O7: bonus soaked +0.4
A8: WAT-4a | B8: Water | C8: 4 | D8: Float | E8: ᚦ | F8: WAT-4b | G8: =IFERROR(INDEX($D:$D,MATCH($F8,$A:$A,0)),"") -> Drown | H8: =IFERROR(INDEX($E:$E,MATCH($F8,$A:$A,0)),"") -> ᚧ | I8: =Water!$E$12 -> buoyancy: lift, lighten, walk on water | J8: U+16A6 | K8: Link | L8: -0.5 | M8: =IFERROR(INDEX('Bond Rules'!$B$4:$B$7,MATCH(K8,'Bond Rules'!$A$4:$A$7,0)),"") -> 2 | N8: =IFERROR(ROUND('Bond Rules'!$B$9+L8*INDEX('Bond Rules'!$C$4:$C$7,MATCH(K8,'Bond Rules'!$A$4:$A$7,0)),2),"") -> 2 | O8: status aloft
A9: WAT-4b | B9: Water | C9: 4 | D9: Drown | E9: ᚧ | F9: WAT-4a | G9: =IFERROR(INDEX($D:$D,MATCH($F9,$A:$A,0)),"") -> Float | H9: =IFERROR(INDEX($E:$E,MATCH($F9,$A:$A,0)),"") -> ᚦ | I9: =Water!$E$13 -> water in the lungs: no casting, no calls for help, damage over time | J9: U+16A7 | K9: Cap | L9: 0.9 | M9: =IFERROR(INDEX('Bond Rules'!$B$4:$B$7,MATCH(K9,'Bond Rules'!$A$4:$A$7,0)),"") -> 1 | N9: =IFERROR(ROUND('Bond Rules'!$B$9+L9*INDEX('Bond Rules'!$C$4:$C$7,MATCH(K9,'Bond Rules'!$A$4:$A$7,0)),2),"") -> 3.85 | O9: interrupts; status dazed
A10: WAT-5a | B10: Water | C10: 5 | D10: Gush | E10: ᚨ | F10: WAT-5b | G10: =IFERROR(INDEX($D:$D,MATCH($F10,$A:$A,0)),"") -> Drip | H10: =IFERROR(INDEX($E:$E,MATCH($F10,$A:$A,0)),"") -> ᚩ | I10: =Water!$E$14 -> a sudden forceful jet | J10: U+16A8 | K10: Link | L10: -0.8 | M10: =IFERROR(INDEX('Bond Rules'!$B$4:$B$7,MATCH(K10,'Bond Rules'!$A$4:$A$7,0)),"") -> 2 | N10: =IFERROR(ROUND('Bond Rules'!$B$9+L10*INDEX('Bond Rules'!$C$4:$C$7,MATCH(K10,'Bond Rules'!$A$4:$A$7,0)),2),"") -> 1.7 | O10: speed x1.3; power x1.1
A11: WAT-5b | B11: Water | C11: 5 | D11: Drip | E11: ᚩ | F11: WAT-5a | G11: =IFERROR(INDEX($D:$D,MATCH($F11,$A:$A,0)),"") -> Gush | H11: =IFERROR(INDEX($E:$E,MATCH($F11,$A:$A,0)),"") -> ᚨ | I11: =Water!$E$15 -> a slow steady trickle that wears and lingers | J11: U+16A9 | K11: Link | L11: 0.3 | M11: =IFERROR(INDEX('Bond Rules'!$B$4:$B$7,MATCH(K11,'Bond Rules'!$A$4:$A$7,0)),"") -> 2 | N11: =IFERROR(ROUND('Bond Rules'!$B$9+L11*INDEX('Bond Rules'!$C$4:$C$7,MATCH(K11,'Bond Rules'!$A$4:$A$7,0)),2),"") -> 2.8 | O11: duration x1.4; cost x0.85
A12: WAT-6a | B12: Water | C12: 6 | D12: Sweep | E12: ᚪ | F12: WAT-6b | G12: =IFERROR(INDEX($D:$D,MATCH($F12,$A:$A,0)),"") -> Settle | H12: =IFERROR(INDEX($E:$E,MATCH($F12,$A:$A,0)),"") -> ᚫ | I12: =Water!$E$16 -> a current that carries things along | J12: U+16AA | K12: Link | L12: -0.4 | M12: =IFERROR(INDEX('Bond Rules'!$B$4:$B$7,MATCH(K12,'Bond Rules'!$A$4:$A$7,0)),"") -> 2 | N12: =IFERROR(ROUND('Bond Rules'!$B$9+L12*INDEX('Bond Rules'!$C$4:$C$7,MATCH(K12,'Bond Rules'!$A$4:$A$7,0)),2),"") -> 2.1 | O12: reach x1.3
A13: WAT-6b | B13: Water | C13: 6 | D13: Settle | E13: ᚫ | F13: WAT-6a | G13: =IFERROR(INDEX($D:$D,MATCH($F13,$A:$A,0)),"") -> Sweep | H13: =IFERROR(INDEX($E:$E,MATCH($F13,$A:$A,0)),"") -> ᚪ | I13: =Water!$E$17 -> the water goes still, and what it carries sinks and stays | J13: U+16AB | K13: Frame | L13: 0.4 | M13: =IFERROR(INDEX('Bond Rules'!$B$4:$B$7,MATCH(K13,'Bond Rules'!$A$4:$A$7,0)),"") -> 4 | N13: =IFERROR(ROUND('Bond Rules'!$B$9+L13*INDEX('Bond Rules'!$C$4:$C$7,MATCH(K13,'Bond Rules'!$A$4:$A$7,0)),2),"") -> 2.66 | O13: status mired
A14: WAT-7a | B14: Water | C14: 7 | D14: Splash | E14: ᚬ | F14: WAT-7b | G14: =IFERROR(INDEX($D:$D,MATCH($F14,$A:$A,0)),"") -> Seep | H14: =IFERROR(INDEX($E:$E,MATCH($F14,$A:$A,0)),"") -> ᚭ | I14: =Water!$E$18 -> burst outward on contact, spraying those near | J14: U+16AC | K14: Branch | L14: -0.7 | M14: =IFERROR(INDEX('Bond Rules'!$B$4:$B$7,MATCH(K14,'Bond Rules'!$A$4:$A$7,0)),"") -> 3 | N14: =IFERROR(ROUND('Bond Rules'!$B$9+L14*INDEX('Bond Rules'!$C$4:$C$7,MATCH(K14,'Bond Rules'!$A$4:$A$7,0)),2),"") -> 2.01 | O14: reach x1.25; power x0.9
A15: WAT-7b | B15: Water | C15: 7 | D15: Seep | E15: ᚭ | F15: WAT-7a | G15: =IFERROR(INDEX($D:$D,MATCH($F15,$A:$A,0)),"") -> Splash | H15: =IFERROR(INDEX($E:$E,MATCH($F15,$A:$A,0)),"") -> ᚬ | I15: =Water!$E$19 -> soak in slowly, getting behind shields and armour | J15: U+16AD | K15: Link | L15: 0.4 | M15: =IFERROR(INDEX('Bond Rules'!$B$4:$B$7,MATCH(K15,'Bond Rules'!$A$4:$A$7,0)),"") -> 2 | N15: =IFERROR(ROUND('Bond Rules'!$B$9+L15*INDEX('Bond Rules'!$C$4:$C$7,MATCH(K15,'Bond Rules'!$A$4:$A$7,0)),2),"") -> 2.9 | O15: pierce +1
